sql.py:25,21:17:44:start:120:p6dtqw -- STARTING SQL testing2020-04-25 21:17:44.311606 /home/henry/pydocs/data/527e4afc-4598-400f-8536-afa5324f0ba4/
sql.py:25,21:17:44:start:122:p6dtqw -- setting sys except hook
sql.py:25,21:17:44:start:132:p6dtqw -- Owner name: testing2020-04-04 25 AprB9U-bL0hVA
configlo:25,21:17:45:handle_exception:82:p6dtqw -- Custom Uncaught exception
Traceback (most recent call last):
  File "/usr/lib/python3.8/runpy.py", line 193, in _run_module_as_main
    return _run_code(code, main_globals, None,
  File "/usr/lib/python3.8/runpy.py", line 86, in _run_code
    exec(code, run_globals)
  File "/home/henry/pydocs/processing/sql.py", line 294, in <module>
    start("testing" + datetime.now().__str__(), wpath)
  File "/home/henry/pydocs/processing/sql.py", line 136, in start
    logger.info("Added owner row, name: %s id: %s", owner.name, owner.id)
  File "/home/henry/.virtualenvs/pydocs/lib/python3.8/site-packages/sqlalchemy/orm/attributes.py", line 286, in __get__
    return self.impl.get(instance_state(instance), dict_)
  File "/home/henry/.virtualenvs/pydocs/lib/python3.8/site-packages/sqlalchemy/orm/attributes.py", line 717, in get
    value = state._load_expired(state, passive)
  File "/home/henry/.virtualenvs/pydocs/lib/python3.8/site-packages/sqlalchemy/orm/state.py", line 652, in _load_expired
    self.manager.deferred_scalar_loader(self, toload)
  File "/home/henry/.virtualenvs/pydocs/lib/python3.8/site-packages/sqlalchemy/orm/loading.py", line 944, in load_scalar_attributes
    raise orm_exc.DetachedInstanceError(
sqlalchemy.orm.exc.DetachedInstanceError: Instance <Owner at 0x7f56695e89d0> is not bound to a Session; attribute refresh operation cannot proceed (Background on this error at: http://sqlalche.me/e/bhk3)
configlo:25,21:17:45:mp_sendmail:115:p6dtqw -- sending mail
configlo:25,21:17:46:handle_exception:86:p6dtqw -- exiting! from sshook
