configlo:27,10:36:34:handle_exception:84:Mahrnw -- Custom Uncaught exception
Traceback (most recent call last):
  File "<stdin>", line 1, in <module>
ModuleNotFoundError: No module named 'gdoc'
configlo:27,10:36:34:handle_exception:88:Mahrnw -- exiting! from sshook
configlo:27,10:36:47:handle_exception:84:Mahrnw -- Custom Uncaught exception
Traceback (most recent call last):
  File "<stdin>", line 1, in <module>
ModuleNotFoundError: No module named 'gdoc'
configlo:27,10:36:47:handle_exception:88:Mahrnw -- exiting! from sshook
configlo:27,10:37:55:handle_exception:84:Mahrnw -- Custom Uncaught exception
Traceback (most recent call last):
  File "<stdin>", line 1, in <module>
  File "/home/henry/pydocs/processing/gdoc.py", line 74, in download_details
    logger.info("received job for %s",self.fileId)
AttributeError: fileId
configlo:27,10:37:55:handle_exception:88:Mahrnw -- exiting! from sshook
configlo:27,10:38:16:handle_exception:84:Mahrnw -- Custom Uncaught exception
Traceback (most recent call last):
  File "/home/henry/pydocs/processing/gdoc.py", line 86, in download_details
    response = requests.get(url = url, headers = self.headers, timeout = 3)
AttributeError: headers

During handling of the above exception, another exception occurred:

Traceback (most recent call last):
  File "<stdin>", line 1, in <module>
  File "/home/henry/pydocs/processing/gdoc.py", line 91, in download_details
    time.sleep(random.uniform(5, 20*i))
KeyboardInterrupt
configlo:27,10:38:16:handle_exception:88:Mahrnw -- exiting! from sshook
configlo:27,10:39:14:handle_exception:84:Mahrnw -- Custom Uncaught exception
Traceback (most recent call last):
  File "<stdin>", line 1, in <module>
AttributeError: headers
configlo:27,10:39:14:handle_exception:88:Mahrnw -- exiting! from sshook
configlo:27,10:39:21:handle_exception:84:Mahrnw -- Custom Uncaught exception
Traceback (most recent call last):
  File "<stdin>", line 1, in <module>
AttributeError: headers
configlo:27,10:39:21:handle_exception:88:Mahrnw -- exiting! from sshook
configlo:27,10:39:34:handle_exception:84:Mahrnw -- Custom Uncaught exception
Traceback (most recent call last):
  File "<stdin>", line 1, in <module>
  File "/home/henry/.virtualenvs/pydocs/lib/python3.8/site-packages/google/auth/credentials.py", line 100, in apply
    headers['authorization'] = 'Bearer {}'.format(
TypeError: 'int' object does not support item assignment
configlo:27,10:39:34:handle_exception:88:Mahrnw -- exiting! from sshook
configlo:27,10:39:39:handle_exception:84:Mahrnw -- Custom Uncaught exception
Traceback (most recent call last):
  File "<stdin>", line 1, in <module>
  File "/home/henry/.virtualenvs/pydocs/lib/python3.8/site-packages/google/auth/credentials.py", line 100, in apply
    headers['authorization'] = 'Bearer {}'.format(
TypeError: 'int' object does not support item assignment
configlo:27,10:39:39:handle_exception:88:Mahrnw -- exiting! from sshook
configlo:27,10:40:48:handle_exception:84:Mahrnw -- Custom Uncaught exception
Traceback (most recent call last):
  File "<stdin>", line 1, in <module>
  File "/home/henry/pydocs/processing/gdoc.py", line 111, in download_details
    pipe.send(dates)
  File "/usr/lib/python3.8/multiprocessing/connection.py", line 206, in send
    self._send_bytes(_ForkingPickler.dumps(obj))
  File "/usr/lib/python3.8/multiprocessing/connection.py", line 405, in _send_bytes
    self._send(buf)
  File "/usr/lib/python3.8/multiprocessing/connection.py", line 368, in _send
    n = write(self._handle, buf)
KeyboardInterrupt
configlo:27,10:40:48:handle_exception:88:Mahrnw -- exiting! from sshook
configlo:27,10:41:57:handle_exception:84:Mahrnw -- Custom Uncaught exception
Traceback (most recent call last):
  File "<stdin>", line 1, in <module>
  File "/home/henry/pydocs/processing/gdoc.py", line 105, in download_details
    pipe.send(dates)
  File "/usr/lib/python3.8/multiprocessing/connection.py", line 206, in send
    self._send_bytes(_ForkingPickler.dumps(obj))
  File "/usr/lib/python3.8/multiprocessing/connection.py", line 404, in _send_bytes
    self._send(header)
  File "/usr/lib/python3.8/multiprocessing/connection.py", line 368, in _send
    n = write(self._handle, buf)
KeyboardInterrupt
configlo:27,10:41:57:handle_exception:88:Mahrnw -- exiting! from sshook
configlo:27,10:42:55:handle_exception:84:Mahrnw -- Custom Uncaught exception
Traceback (most recent call last):
  File "<stdin>", line 1, in <module>
  File "/usr/lib/python3.8/importlib/__init__.py", line 140, in reload
    raise TypeError("reload() argument must be a module")
TypeError: reload() argument must be a module
configlo:27,10:42:55:handle_exception:88:Mahrnw -- exiting! from sshook
configlo:27,10:43:25:handle_exception:84:Mahrnw -- Custom Uncaught exception
Traceback (most recent call last):
  File "<stdin>", line 1, in <module>
NameError: name 'ga' is not defined
configlo:27,10:43:25:handle_exception:88:Mahrnw -- exiting! from sshook
