configlo:27,11:56:33:handle_exception:84:skKjkQ -- Custom Uncaught exception
Traceback (most recent call last):
  File "/usr/lib/python3.8/runpy.py", line 193, in _run_module_as_main
    return _run_code(code, main_globals, None,
  File "/usr/lib/python3.8/runpy.py", line 86, in _run_code
    exec(code, run_globals)
  File "/home/henry/pydocs/processing/sql.py", line 325, in <module>
    start("testing" + datetime.now().__str__(), wpath)
  File "/home/henry/pydocs/processing/sql.py", line 298, in start
    adder(lt_filenames, sess)
  File "/home/henry/pydocs/processing/sql.py", line 51, in adder
    sess.add(i)
  File "/home/henry/.virtualenvs/pydocs/lib/python3.8/site-packages/sqlalchemy/orm/session.py", line 1981, in add
    self._save_or_update_state(state)
  File "/home/henry/.virtualenvs/pydocs/lib/python3.8/site-packages/sqlalchemy/orm/session.py", line 1994, in _save_or_update_state
    self._save_or_update_impl(state)
  File "/home/henry/.virtualenvs/pydocs/lib/python3.8/site-packages/sqlalchemy/orm/session.py", line 2344, in _save_or_update_impl
    self._save_impl(state)
  File "/home/henry/.virtualenvs/pydocs/lib/python3.8/site-packages/sqlalchemy/orm/session.py", line 2297, in _save_impl
    to_attach = self._before_attach(state, obj)
  File "/home/henry/.virtualenvs/pydocs/lib/python3.8/site-packages/sqlalchemy/orm/session.py", line 2414, in _before_attach
    raise sa_exc.InvalidRequestError(
sqlalchemy.exc.InvalidRequestError: Object '<Filename at 0x7f9494912f70>' is already attached to session '2' (this is '3')
configlo:27,11:56:33:handle_exception:88:skKjkQ -- exiting! from sshook
