dsds.py:25,18:12:31:start:18:8cFMQw -- start
get_file:25,18:12:40:loadFiles:282:8cFMQw -- Start loadFiles, 527e4afc-4598-400f-8536-afa5324f0ba4 0B4Fujvv5MfqbVElBU01fZUxHcUk
requests:25,18:12:40:__call__:117:8cFMQw -- Making request: POST https://oauth2.googleapis.com/token
connecti:25,18:12:40:_new_conn:817:8cFMQw -- Starting new HTTPS connection (1): oauth2.googleapis.com
connecti:25,18:12:40:_make_request:393:8cFMQw -- https://oauth2.googleapis.com:443 "POST /token HTTP/1.1" 200 None
selector:25,18:12:40:__init__:59:8cFMQw -- Using selector: EpollSelector
test_uti:25,18:12:40:print_size:82:8cFMQw -- ---------------Memory usage: 90460 (kb)---------------0 mins since start
test_uti:25,18:12:40:print_size:88:8cFMQw -- /usr/lib/python3.8/tracemalloc.py:397: size=512 B (+512 B), count=3 (+3), average=171 B
test_uti:25,18:12:40:print_size:88:8cFMQw -- /usr/lib/python3.8/tracemalloc.py:534: size=472 B (+472 B), count=2 (+2), average=236 B
test_uti:25,18:12:40:print_size:88:8cFMQw -- /home/henry/pydocs/processing/datutils/test_utils.py:82: size=448 B (+448 B), count=1 (+1), average=448 B
test_uti:25,18:12:40:print_size:88:8cFMQw -- /home/henry/pydocs/processing/datutils/test_utils.py:86: size=424 B (+424 B), count=1 (+1), average=424 B
test_uti:25,18:12:40:print_size:88:8cFMQw -- /home/henry/pydocs/processing/datutils/test_utils.py:79: size=0 B (-424 B), count=0 (-1)
test_uti:25,18:12:40:print_size:88:8cFMQw -- /home/henry/pydocs/processing/datutils/test_utils.py:80: size=400 B (+400 B), count=1 (+1), average=400 B
test_uti:25,18:12:40:print_size:88:8cFMQw -- /usr/lib/python3.8/logging/__init__.py:330: size=48 B (+48 B), count=2 (+2), average=24 B
test_uti:25,18:12:40:print_size:88:8cFMQw -- /usr/lib/python3.8/tracemalloc.py:291: size=40 B (+40 B), count=1 (+1), average=40 B
test_uti:25,18:12:40:print_size:88:8cFMQw -- /usr/lib/python3.8/logging/__init__.py:329: size=24 B (+24 B), count=1 (+1), average=24 B
test_uti:25,18:12:40:print_size:88:8cFMQw -- /usr/lib/python3.8/logging/__init__.py:289: size=24 B (+24 B), count=1 (+1), average=24 B
test_uti:25,18:12:40:print_size:90:8cFMQw -- 

------------------------------


test_uti:25,18:12:40:print_size:93:8cFMQw -- /usr/lib/python3.8/tracemalloc.py:397: size=512 B, count=3, average=171 B
test_uti:25,18:12:40:print_size:93:8cFMQw -- /usr/lib/python3.8/tracemalloc.py:534: size=472 B, count=2, average=236 B
test_uti:25,18:12:40:print_size:93:8cFMQw -- /home/henry/pydocs/processing/datutils/test_utils.py:82: size=448 B, count=1, average=448 B
test_uti:25,18:12:40:print_size:93:8cFMQw -- /home/henry/pydocs/processing/datutils/test_utils.py:86: size=424 B, count=1, average=424 B
test_uti:25,18:12:40:print_size:93:8cFMQw -- /home/henry/pydocs/processing/datutils/test_utils.py:80: size=400 B, count=1, average=400 B
test_uti:25,18:12:40:print_size:93:8cFMQw -- /usr/lib/python3.8/logging/__init__.py:330: size=48 B, count=2, average=24 B
test_uti:25,18:12:40:print_size:93:8cFMQw -- /usr/lib/python3.8/tracemalloc.py:291: size=40 B, count=1, average=40 B
test_uti:25,18:12:40:print_size:93:8cFMQw -- /usr/lib/python3.8/logging/__init__.py:329: size=24 B, count=1, average=24 B
test_uti:25,18:12:40:print_size:93:8cFMQw -- /usr/lib/python3.8/logging/__init__.py:289: size=24 B, count=1, average=24 B
test_uti:25,18:12:40:print_size:93:8cFMQw -- /home/henry/pydocs/processing/datutils/test_utils.py:83: size=24 B, count=1, average=24 B
test_uti:25,18:12:40:print_size:100:8cFMQw -- /home/henry/pydocs/data/527e4afc-4598-400f-8536-afa5324f0ba4/
0/0 at 2020-04-25 18:12:40.445282
dumped: 0
get_file:25,18:12:41:getIdsRecursive:53:8cFMQw -- getIdsRecursive looping
get_file:25,18:12:42:getIdsRecursive:53:8cFMQw -- getIdsRecursive looping
get_file:25,18:12:44:getIdsRecursive:53:8cFMQw -- getIdsRecursive looping
get_file:25,18:12:44:getIdsRecursive:53:8cFMQw -- getIdsRecursive looping
test_uti:25,18:12:45:print_size:82:8cFMQw -- ---------------Memory usage: 90892 (kb)---------------0 mins since start
test_uti:25,18:12:45:print_size:88:8cFMQw -- /home/henry/pydocs/processing/datutils/test_utils.py:158: size=13.7 KiB (+13.7 KiB), count=182 (+182), average=77 B
test_uti:25,18:12:45:print_size:88:8cFMQw -- <frozen importlib._bootstrap_external>:580: size=10.9 KiB (+10.9 KiB), count=114 (+114), average=98 B
test_uti:25,18:12:45:print_size:88:8cFMQw -- /usr/lib/python3.8/abc.py:102: size=9631 B (+9631 B), count=100 (+100), average=96 B
test_uti:25,18:12:45:print_size:88:8cFMQw -- /usr/lib/python3.8/ssl.py:906: size=5500 B (+5500 B), count=87 (+87), average=63 B
test_uti:25,18:12:45:print_size:88:8cFMQw -- /usr/lib/python3.8/asyncio/events.py:81: size=5104 B (+5104 B), count=16 (+16), average=319 B
test_uti:25,18:12:45:print_size:88:8cFMQw -- /home/henry/pydocs/processing/get_files.py:108: size=4496 B (+4496 B), count=110 (+110), average=41 B
test_uti:25,18:12:45:print_size:88:8cFMQw -- /usr/lib/python3.8/concurrent/futures/thread.py:109: size=2999 B (+2999 B), count=12 (+12), average=250 B
test_uti:25,18:12:45:print_size:88:8cFMQw -- /home/henry/pydocs/processing/get_files.py:100: size=2807 B (+2807 B), count=35 (+35), average=80 B
test_uti:25,18:12:45:print_size:88:8cFMQw -- /home/henry/.virtualenvs/pydocs/lib/python3.8/site-packages/aiohttp/http_parser.py:714: size=2746 B (+2746 B), count=1 (+1), average=2746 B
test_uti:25,18:12:45:print_size:88:8cFMQw -- /home/henry/.virtualenvs/pydocs/lib/python3.8/site-packages/aiohttp/client_reqrep.py:363: size=2016 B (+2016 B), count=2 (+2), average=1008 B
test_uti:25,18:12:45:print_size:90:8cFMQw -- 

------------------------------


test_uti:25,18:12:45:print_size:93:8cFMQw -- /home/henry/pydocs/processing/datutils/test_utils.py:158: size=13.7 KiB, count=182, average=77 B
test_uti:25,18:12:45:print_size:93:8cFMQw -- <frozen importlib._bootstrap_external>:580: size=10.9 KiB, count=114, average=98 B
test_uti:25,18:12:45:print_size:93:8cFMQw -- /usr/lib/python3.8/abc.py:102: size=9631 B, count=100, average=96 B
test_uti:25,18:12:45:print_size:93:8cFMQw -- /usr/lib/python3.8/ssl.py:906: size=5500 B, count=87, average=63 B
test_uti:25,18:12:45:print_size:93:8cFMQw -- /usr/lib/python3.8/asyncio/events.py:81: size=5104 B, count=16, average=319 B
test_uti:25,18:12:45:print_size:93:8cFMQw -- /home/henry/pydocs/processing/get_files.py:108: size=4496 B, count=110, average=41 B
test_uti:25,18:12:45:print_size:93:8cFMQw -- /usr/lib/python3.8/concurrent/futures/thread.py:109: size=2999 B, count=12, average=250 B
test_uti:25,18:12:45:print_size:93:8cFMQw -- /home/henry/pydocs/processing/get_files.py:100: size=2807 B, count=35, average=80 B
test_uti:25,18:12:45:print_size:93:8cFMQw -- /home/henry/.virtualenvs/pydocs/lib/python3.8/site-packages/aiohttp/http_parser.py:714: size=2746 B, count=1, average=2746 B
test_uti:25,18:12:45:print_size:93:8cFMQw -- /home/henry/.virtualenvs/pydocs/lib/python3.8/site-packages/aiohttp/client_reqrep.py:363: size=2016 B, count=2, average=1008 B
test_uti:25,18:12:45:print_size:100:8cFMQw -- /home/henry/pydocs/data/527e4afc-4598-400f-8536-afa5324f0ba4/
0/28 at 2020-04-25 18:12:45.514390
dumped: 0
get_file:25,18:12:46:getIdsRecursive:53:8cFMQw -- getIdsRecursive looping
get_file:25,18:12:46:getIdsRecursive:53:8cFMQw -- getIdsRecursive looping
get_file:25,18:12:46:getIdsRecursive:53:8cFMQw -- getIdsRecursive looping
get_file:25,18:12:47:getRevision:166:8cFMQw -- getRevision looping
gdoc.py:25,18:12:47:async_init:24:8cFMQw -- async init called
get_file:25,18:12:47:getIdsRecursive:53:8cFMQw -- getIdsRecursive looping
get_file:25,18:12:47:getIdsRecursive:53:8cFMQw -- getIdsRecursive looping
gdoc.py:25,18:12:47:get_last_revision:53:8cFMQw -- last revision id 394
gdoc.py:25,18:12:47:async_init:33:8cFMQw -- after await 394
connecti:25,18:12:47:_new_conn:817:8cFMQw -- Starting new HTTPS connection (1): docs.google.com
connecti:25,18:12:48:_make_request:393:8cFMQw -- https://docs.google.com:443 "GET /document/d/1TYIOfz_uzybWgEeexs8iE64jcjt-AmUegOP6KORNaWQ/revisions/load?id=1TYIOfz_uzybWgEeexs8iE64jcjt-AmUegOP6KORNaWQ&start=1&end=394 HTTP/1.1" 200 None
gdoc.py:25,18:12:48:download_details:69:8cFMQw -- Cannot get revisions.json
Traceback (most recent call last):
  File "/home/henry/pydocs/processing/gdoc.py", line 67, in download_details
    assert response.status == 200
AttributeError: 'Response' object has no attribute 'status'
get_file:25,18:12:48:getRevision:197:8cFMQw -- []
get_file:25,18:12:48:getRevision:200:8cFMQw -- google doc
get_file:25,18:12:48:getRevision:166:8cFMQw -- getRevision looping
gdoc.py:25,18:12:48:async_init:24:8cFMQw -- async init called
get_file:25,18:12:48:getIdsRecursive:53:8cFMQw -- getIdsRecursive looping
get_file:25,18:12:48:getRevision:166:8cFMQw -- getRevision looping
gdoc.py:25,18:12:48:async_init:24:8cFMQw -- async init called
get_file:25,18:12:48:getIdsRecursive:53:8cFMQw -- getIdsRecursive looping
gdoc.py:25,18:12:49:get_last_revision:53:8cFMQw -- last revision id 1336
gdoc.py:25,18:12:49:async_init:33:8cFMQw -- after await 1336
connecti:25,18:12:49:_new_conn:817:8cFMQw -- Starting new HTTPS connection (1): docs.google.com
connecti:25,18:12:49:_make_request:393:8cFMQw -- https://docs.google.com:443 "GET /document/d/19Fu317bfo0V7yOIkfLvKtAU-UJYLf8d2Soy-jTvq1uc/revisions/load?id=19Fu317bfo0V7yOIkfLvKtAU-UJYLf8d2Soy-jTvq1uc&start=1&end=1336 HTTP/1.1" 200 None
gdoc.py:25,18:12:49:download_details:69:8cFMQw -- Cannot get revisions.json
Traceback (most recent call last):
  File "/home/henry/pydocs/processing/gdoc.py", line 67, in download_details
    assert response.status == 200
AttributeError: 'Response' object has no attribute 'status'
get_file:25,18:12:49:getRevision:197:8cFMQw -- []
get_file:25,18:12:49:getRevision:200:8cFMQw -- google doc
get_file:25,18:12:49:getRevision:166:8cFMQw -- getRevision looping
gdoc.py:25,18:12:49:async_init:24:8cFMQw -- async init called
get_file:25,18:12:49:getIdsRecursive:53:8cFMQw -- getIdsRecursive looping
gdoc.py:25,18:12:49:get_last_revision:53:8cFMQw -- last revision id 1946
gdoc.py:25,18:12:49:async_init:33:8cFMQw -- after await 1946
connecti:25,18:12:49:_new_conn:817:8cFMQw -- Starting new HTTPS connection (1): docs.google.com
connecti:25,18:12:50:_make_request:393:8cFMQw -- https://docs.google.com:443 "GET /document/d/1eXJKzIcZCM6pAdVLLrvEyIwQBDDrtm8dComeZ_W7uOI/revisions/load?id=1eXJKzIcZCM6pAdVLLrvEyIwQBDDrtm8dComeZ_W7uOI&start=1&end=1946 HTTP/1.1" 200 None
gdoc.py:25,18:12:50:download_details:69:8cFMQw -- Cannot get revisions.json
Traceback (most recent call last):
  File "/home/henry/pydocs/processing/gdoc.py", line 67, in download_details
    assert response.status == 200
AttributeError: 'Response' object has no attribute 'status'
get_file:25,18:12:50:getRevision:197:8cFMQw -- []
get_file:25,18:12:50:getRevision:200:8cFMQw -- google doc
get_file:25,18:12:50:getRevision:166:8cFMQw -- getRevision looping
get_file:25,18:12:50:getRevision:183:8cFMQw -- not google doc
gdoc.py:25,18:12:50:get_last_revision:53:8cFMQw -- last revision id 12
gdoc.py:25,18:12:50:async_init:33:8cFMQw -- after await 12
connecti:25,18:12:50:_new_conn:817:8cFMQw -- Starting new HTTPS connection (1): docs.google.com
connecti:25,18:12:51:_make_request:393:8cFMQw -- https://docs.google.com:443 "GET /document/d/1Ux4BA5BVJTcsGcTcGp8CtB85ahlWp0h83AGvrtAhnTg/revisions/load?id=1Ux4BA5BVJTcsGcTcGp8CtB85ahlWp0h83AGvrtAhnTg&start=1&end=12 HTTP/1.1" 200 None
gdoc.py:25,18:12:51:download_details:69:8cFMQw -- Cannot get revisions.json
Traceback (most recent call last):
  File "/home/henry/pydocs/processing/gdoc.py", line 67, in download_details
    assert response.status == 200
AttributeError: 'Response' object has no attribute 'status'
get_file:25,18:12:51:getRevision:197:8cFMQw -- []
get_file:25,18:12:51:getRevision:200:8cFMQw -- google doc
get_file:25,18:12:51:getRevision:166:8cFMQw -- getRevision looping
test_uti:25,18:12:51:tryGetQueue:228:8cFMQw -- getIdswaiting 1 5
test_uti:25,18:12:51:print_size:82:8cFMQw -- ---------------Memory usage: 91448 (kb)---------------0 mins since start
test_uti:25,18:12:51:print_size:88:8cFMQw -- <frozen importlib._bootstrap_external>:580: size=79.0 KiB (+68.1 KiB), count=936 (+822), average=86 B
test_uti:25,18:12:51:print_size:88:8cFMQw -- /usr/lib/python3.8/ssl.py:906: size=15.8 KiB (+10.4 KiB), count=256 (+169), average=63 B
test_uti:25,18:12:51:print_size:88:8cFMQw -- /home/henry/pydocs/processing/get_files.py:108: size=11.9 KiB (+7736 B), count=282 (+172), average=43 B
test_uti:25,18:12:51:print_size:88:8cFMQw -- /home/henry/pydocs/processing/datutils/test_utils.py:158: size=18.0 KiB (+4473 B), count=214 (+32), average=86 B
test_uti:25,18:12:51:print_size:88:8cFMQw -- /home/henry/pydocs/processing/get_files.py:100: size=6392 B (+3585 B), count=87 (+52), average=73 B
test_uti:25,18:12:51:print_size:88:8cFMQw -- <frozen importlib._bootstrap>:219: size=3523 B (+3523 B), count=40 (+40), average=88 B
test_uti:25,18:12:51:print_size:88:8cFMQw -- /home/henry/pydocs/processing/get_files.py:103: size=4632 B (+3520 B), count=1 (+0), average=4632 B
test_uti:25,18:12:51:print_size:88:8cFMQw -- /usr/lib/python3.8/multiprocessing/connection.py:114: size=2444 B (+2444 B), count=9 (+9), average=272 B
test_uti:25,18:12:51:print_size:88:8cFMQw -- /usr/lib/python3.8/multiprocessing/util.py:289: size=2344 B (+2344 B), count=2 (+2), average=1172 B
test_uti:25,18:12:51:print_size:88:8cFMQw -- /home/henry/.virtualenvs/pydocs/lib/python3.8/site-packages/aiohttp/streams.py:121: size=2400 B (+2304 B), count=7 (+6), average=343 B
test_uti:25,18:12:51:print_size:90:8cFMQw -- 

------------------------------


test_uti:25,18:12:51:print_size:93:8cFMQw -- <frozen importlib._bootstrap_external>:580: size=79.0 KiB, count=936, average=86 B
test_uti:25,18:12:51:print_size:93:8cFMQw -- /home/henry/pydocs/processing/datutils/test_utils.py:158: size=18.0 KiB, count=214, average=86 B
test_uti:25,18:12:51:print_size:93:8cFMQw -- /usr/lib/python3.8/ssl.py:906: size=15.8 KiB, count=256, average=63 B
test_uti:25,18:12:51:print_size:93:8cFMQw -- /home/henry/pydocs/processing/get_files.py:108: size=11.9 KiB, count=282, average=43 B
test_uti:25,18:12:51:print_size:93:8cFMQw -- /usr/lib/python3.8/abc.py:102: size=9377 B, count=96, average=98 B
test_uti:25,18:12:51:print_size:93:8cFMQw -- /home/henry/pydocs/processing/get_files.py:100: size=6392 B, count=87, average=73 B
test_uti:25,18:12:51:print_size:93:8cFMQw -- /usr/lib/python3.8/asyncio/events.py:81: size=5224 B, count=19, average=275 B
test_uti:25,18:12:51:print_size:93:8cFMQw -- /home/henry/pydocs/processing/get_files.py:103: size=4632 B, count=1, average=4632 B
test_uti:25,18:12:51:print_size:93:8cFMQw -- <frozen importlib._bootstrap>:219: size=3523 B, count=40, average=88 B
test_uti:25,18:12:51:print_size:93:8cFMQw -- /usr/lib/python3.8/concurrent/futures/thread.py:109: size=2999 B, count=12, average=250 B
test_uti:25,18:12:51:print_size:100:8cFMQw -- /home/henry/pydocs/data/527e4afc-4598-400f-8536-afa5324f0ba4/
4/73 at 2020-04-25 18:12:51.227429
dumped: 0
get_file:25,18:12:51:getRevision:166:8cFMQw -- getRevision looping
gdoc.py:25,18:12:52:async_init:24:8cFMQw -- async init called
gdoc.py:25,18:12:52:async_init:24:8cFMQw -- async init called
get_file:25,18:12:52:getRevision:166:8cFMQw -- getRevision looping
gdoc.py:25,18:12:52:async_init:24:8cFMQw -- async init called
gdoc.py:25,18:12:52:get_last_revision:53:8cFMQw -- last revision id 1394
gdoc.py:25,18:12:52:async_init:33:8cFMQw -- after await 1394
connecti:25,18:12:52:_new_conn:817:8cFMQw -- Starting new HTTPS connection (1): docs.google.com
connecti:25,18:12:53:_make_request:393:8cFMQw -- https://docs.google.com:443 "GET /document/d/1K6SwyWCOhW6dt906DjOIhJ-ZklpsooCdTyYHGfEZD2s/revisions/load?id=1K6SwyWCOhW6dt906DjOIhJ-ZklpsooCdTyYHGfEZD2s&start=1&end=1394 HTTP/1.1" 200 None
gdoc.py:25,18:12:53:download_details:69:8cFMQw -- Cannot get revisions.json
Traceback (most recent call last):
  File "/home/henry/pydocs/processing/gdoc.py", line 67, in download_details
    assert response.status == 200
AttributeError: 'Response' object has no attribute 'status'
get_file:25,18:12:53:getRevision:197:8cFMQw -- []
get_file:25,18:12:53:getRevision:200:8cFMQw -- google doc
get_file:25,18:12:53:getRevision:166:8cFMQw -- getRevision looping
gdoc.py:25,18:12:53:get_last_revision:53:8cFMQw -- last revision id 1782
gdoc.py:25,18:12:53:async_init:33:8cFMQw -- after await 1782
connecti:25,18:12:53:_new_conn:817:8cFMQw -- Starting new HTTPS connection (1): docs.google.com
configlo:25,18:12:53:handle_exception:82:8cFMQw -- Custom Uncaught exception
Traceback (most recent call last):
  File "dsds.py", line 37, in <module>
    start()
  File "dsds.py", line 34, in start
    loadFiles(uid, workingPath, fileid, creds)
  File "/home/henry/pydocs/processing/get_files.py", line 307, in loadFiles
    loop.run_until_complete(asyncio.gather(startTask))
  File "/usr/lib/python3.8/asyncio/base_events.py", line 603, in run_until_complete
    self.run_forever()
  File "/usr/lib/python3.8/asyncio/base_events.py", line 570, in run_forever
    self._run_once()
  File "/usr/lib/python3.8/asyncio/base_events.py", line 1859, in _run_once
    handle._run()
  File "/usr/lib/python3.8/asyncio/events.py", line 81, in _run
    self._context.run(self._callback, *self._args)
  File "/home/henry/pydocs/processing/get_files.py", line 194, in getRevision
    dates = parent_conn.recv()
  File "/usr/lib/python3.8/multiprocessing/connection.py", line 250, in recv
    buf = self._recv_bytes()
  File "/usr/lib/python3.8/multiprocessing/connection.py", line 414, in _recv_bytes
    buf = self._recv(4)
  File "/usr/lib/python3.8/multiprocessing/connection.py", line 379, in _recv
    chunk = read(handle, remaining)
KeyboardInterrupt
configlo:25,18:12:53:sendmail:103:8cFMQw -- sending mail
gdoc.py:25,18:12:53:download_details:69:8cFMQw -- Cannot get revisions.json
Traceback (most recent call last):
  File "/home/henry/pydocs/processing/gdoc.py", line 66, in download_details
    response = requests.get(url = url, headers = self.headers)
  File "/home/henry/.virtualenvs/pydocs/lib/python3.8/site-packages/requests/api.py", line 72, in get
    return request('get', url, params=params, **kwargs)
  File "/home/henry/.virtualenvs/pydocs/lib/python3.8/site-packages/requests/api.py", line 58, in request
    return session.request(method=method, url=url, **kwargs)
  File "/home/henry/.virtualenvs/pydocs/lib/python3.8/site-packages/requests/sessions.py", line 502, in request
    resp = self.send(prep, **send_kwargs)
  File "/home/henry/.virtualenvs/pydocs/lib/python3.8/site-packages/requests/sessions.py", line 612, in send
    r = adapter.send(request, **kwargs)
  File "/home/henry/.virtualenvs/pydocs/lib/python3.8/site-packages/requests/adapters.py", line 430, in send
    resp = conn.urlopen(
  File "/home/henry/.virtualenvs/pydocs/lib/python3.8/site-packages/urllib3/connectionpool.py", line 597, in urlopen
    httplib_response = self._make_request(conn, method, url,
  File "/home/henry/.virtualenvs/pydocs/lib/python3.8/site-packages/urllib3/connectionpool.py", line 345, in _make_request
    self._validate_conn(conn)
  File "/home/henry/.virtualenvs/pydocs/lib/python3.8/site-packages/urllib3/connectionpool.py", line 844, in _validate_conn
    conn.connect()
  File "/home/henry/.virtualenvs/pydocs/lib/python3.8/site-packages/urllib3/connection.py", line 284, in connect
    conn = self._new_conn()
  File "/home/henry/.virtualenvs/pydocs/lib/python3.8/site-packages/urllib3/connection.py", line 140, in _new_conn
    conn = connection.create_connection(
  File "/home/henry/.virtualenvs/pydocs/lib/python3.8/site-packages/urllib3/util/connection.py", line 73, in create_connection
    sock.connect(sa)
KeyboardInterrupt
configlo:25,18:12:55:handle_exception:86:8cFMQw -- exiting! from sshook
