sql.py:26,08:58:38:start:177:7v22jQ -- STARTING SQL testing2020-04-26 08:58:38.723404 /home/henry/pydocs/data/527e4afc-4598-400f-8536-afa5324f0ba4/
sql.py:26,08:58:38:start:179:7v22jQ -- setting sys except hook
sql.py:26,08:58:38:start:186:7v22jQ -- Owner name: testing2020-04-04 26 AprQR4xlOGnng
sql.py:26,08:58:39:start:190:7v22jQ -- Added owner row, name: testing2020-04-04 26 AprQR4xlOGnng id: 112
sql.py:26,08:58:39:load_from_dict:111:7v22jQ -- File: 0B4Fujvv5Mfqbb2d0TnNhcFhhREdadmRaaEI3QzVabnE2NE5v
sql.py:26,08:58:39:load_from_dict:111:7v22jQ -- File: 1QNNRjwRnVqieEoA5i9CdaSCyT_6Bi4vkmGO8YuZHytU
sql.py:26,08:58:39:load_from_dict:111:7v22jQ -- File: 1cGlmEaWYTHdD_Y3vlkIMMkZhdmosSZo_rQYxcSBoDbQ
sql.py:26,08:58:39:load_from_dict:111:7v22jQ -- File: 1G-K37QbHDgyLsJaUjRsROtLZZkj1fmqyC5YyHzOh-_Q
sql.py:26,08:58:39:load_from_dict:111:7v22jQ -- File: 1cIWwf3nZ2RAeriW8GerxZHY9nirLdcc968-GgSnRkjQ
sql.py:26,08:58:39:load_from_dict:111:7v22jQ -- File: 16wsJnYBwdOHbuGROxWDFe2Tcf1w8T49TwWnGvq5OjXY
sql.py:26,08:58:39:load_from_dict:111:7v22jQ -- File: 1VJe9pAq5wUkMz1cgNAOYLtvRbDehNWGZLwq4vtX3QVQ
sql.py:26,08:58:39:load_from_dict:111:7v22jQ -- File: 12NnsHOjtevUATb-yYIgDFFLyYajiHxhJ6xHiJnIXj-8
sql.py:26,08:58:39:load_from_dict:111:7v22jQ -- File: 1LcO1aZmE6Jap4GF5ZpBGetjUSFeVBYg__DgWYlDwWY4
sql.py:26,08:58:39:load_from_dict:111:7v22jQ -- File: 1JEcM-IFEodRvDg7EE9AntQ4wwOBTRXcDFqRK5SR2I08
sql.py:26,08:58:39:load_from_dict:111:7v22jQ -- File: 1C09g5-ATBpXNJOmH8ANwCnq7Pk6vClzI1lmFYcqaH6A
sql.py:26,08:58:39:load_from_dict:111:7v22jQ -- File: 1NpTHMCkLa6lHL9Ok8a9hejyXihpujcQpVgSa7JNBP6s
sql.py:26,08:58:39:load_from_dict:111:7v22jQ -- File: 17MhIJt6Bl2HnDLFiNZPRh7UOx-Co9FMvPWBsRnJRfsM
sql.py:26,08:58:39:load_from_dict:111:7v22jQ -- File: 1B37ygx-Iwh0EpS1c5fqpbK6AqE39m6ao4WD4uMWknzc
sql.py:26,08:58:39:load_from_dict:111:7v22jQ -- File: 1jRrZTHn-oge2sTqxli8Um026xuniXAeezLZn4B2zVSg
sql.py:26,08:58:39:load_from_dict:111:7v22jQ -- File: 1D48Gz6hmPkE6sATNqYoA3P3Hdjtq1y2zHRjrh1kH64I
sql.py:26,08:58:39:load_from_dict:111:7v22jQ -- File: 1cctIQ_TyhvRFgFVkzjwcfDL1w0i4L2lF-78_WM7Hy6A
sql.py:26,08:58:39:load_from_dict:111:7v22jQ -- File: 1o6ARVj7jhE2K_VNnX2BYajR2XBX1kdMu
sql.py:26,08:58:39:load_from_dict:111:7v22jQ -- File: 15e68EIS9xXe5Yvzju4GtkyhFKJ_UgUA9juJKiUpPeUA
sql.py:26,08:58:39:load_from_dict:111:7v22jQ -- File: 186ge00t4G7kcx1QdCIHxRhTnZfzpSTGDgfAXkdbD_Ig
sql.py:26,08:58:39:load_from_dict:111:7v22jQ -- File: 1wfaH9BSg8wrDaKXR54KK1y8pd-miEOQNj3E8GL6fTfg
sql.py:26,08:58:39:load_from_dict:111:7v22jQ -- File: 1G1g252JtmrFnXI5HaLLEafe8apipzquYwQQ0hbQIaho
sql.py:26,08:58:39:load_from_dict:111:7v22jQ -- File: 1sF1pFtL8fsnQBBAoTt8P7YGOVZVr6-6a4BLeU3PBncI
sql.py:26,08:58:39:load_from_dict:111:7v22jQ -- File: 1LuJ1Ln_dAc7n3Qj0zNE4yuYfFG6NEgxO-hsDA9M4qpQ
sql.py:26,08:58:39:load_from_dict:111:7v22jQ -- File: 15Fi6RHQtC8H-GOJC_gjiED_9rNxtCdahEGtLvBUZcv4
sql.py:26,08:58:39:load_from_dict:111:7v22jQ -- File: 1H1aSubiwctKw-qMV6t1aGlfooY2Qn9V6Y01phHpg-kw
sql.py:26,08:58:39:load_from_dict:111:7v22jQ -- File: 1WbGMwYDyqP6aCDpf5fBbR7sneMicXtvEtfm3Z4k0Vzs
sql.py:26,08:58:39:load_from_dict:111:7v22jQ -- File: 16wh_FgWE8Y0tUpAdIte4WyuB91_ypCySi82lvdhAiFY
sql.py:26,08:58:39:load_from_dict:111:7v22jQ -- File: 1WKk8W5cG-CYKBYN_cWpAdziiPVhvQZEAarnPwf58z4Y
sql.py:26,08:58:39:load_from_dict:111:7v22jQ -- File: 1YJPVyeYstaXiTguoSGCe_Kb3y4yv49N224nUrfLo7rU
sql.py:26,08:58:39:load_from_dict:111:7v22jQ -- File: 1PscMFhdtA31Nh7ELmM18NqjUfLDeGiexKI6q-lI0fKY
sql.py:26,08:58:39:load_from_dict:111:7v22jQ -- File: 1YlY2MTwu_I6PGWgmkNqFXYJVvNSQKMi7j0WulyoD75w
sql.py:26,08:58:39:load_from_dict:111:7v22jQ -- File: 1Gxvc-37IOivNHIPUJBI1v3jf5e-Hwcby_VZbN-k-Bfc
sql.py:26,08:58:39:load_from_dict:111:7v22jQ -- File: 1T1Sj69DxCTpEQI2pH0O04l_PSx1V3xsxYOnkiHPEPis
sql.py:26,08:58:39:load_from_dict:130:7v22jQ -- len of id map 34 len of files 34
sql.py:26,08:58:39:load_from_dict:135:7v22jQ -- starting bulk save for lt_files
sql.py:26,08:58:43:start:209:7v22jQ -- Finished loading pickles
configlo:26,08:58:47:handle_exception:82:7v22jQ -- Custom Uncaught exception
Traceback (most recent call last):
  File "/usr/lib/python3.8/encodings/utf_16_le.py", line 15, in decode
    def decode(input, errors='strict'):
KeyboardInterrupt

The above exception was the direct cause of the following exception:

KeyboardInterrupt: decoding with 'utf-16le' codec failed (KeyboardInterrupt: )

The above exception was the direct cause of the following exception:

Traceback (most recent call last):
  File "/home/henry/.virtualenvs/pydocs/lib/python3.8/site-packages/sqlalchemy/orm/session.py", line 2597, in _flush
    flush_context.execute()
  File "/home/henry/.virtualenvs/pydocs/lib/python3.8/site-packages/sqlalchemy/orm/unitofwork.py", line 422, in execute
    rec.execute(self)
  File "/home/henry/.virtualenvs/pydocs/lib/python3.8/site-packages/sqlalchemy/orm/unitofwork.py", line 586, in execute
    persistence.save_obj(
  File "/home/henry/.virtualenvs/pydocs/lib/python3.8/site-packages/sqlalchemy/orm/persistence.py", line 239, in save_obj
    _emit_insert_statements(
  File "/home/henry/.virtualenvs/pydocs/lib/python3.8/site-packages/sqlalchemy/orm/persistence.py", line 1135, in _emit_insert_statements
    result = cached_connections[connection].execute(
  File "/home/henry/.virtualenvs/pydocs/lib/python3.8/site-packages/sqlalchemy/engine/base.py", line 984, in execute
    return meth(self, multiparams, params)
  File "/home/henry/.virtualenvs/pydocs/lib/python3.8/site-packages/sqlalchemy/sql/elements.py", line 293, in _execute_on_connection
    return connection._execute_clauseelement(self, multiparams, params)
  File "/home/henry/.virtualenvs/pydocs/lib/python3.8/site-packages/sqlalchemy/engine/base.py", line 1097, in _execute_clauseelement
    ret = self._execute_context(
  File "/home/henry/.virtualenvs/pydocs/lib/python3.8/site-packages/sqlalchemy/engine/base.py", line 1287, in _execute_context
    self._handle_dbapi_exception(
  File "/home/henry/.virtualenvs/pydocs/lib/python3.8/site-packages/sqlalchemy/engine/base.py", line 1485, in _handle_dbapi_exception
    util.raise_(exc_info[1], with_traceback=exc_info[2])
  File "/home/henry/.virtualenvs/pydocs/lib/python3.8/site-packages/sqlalchemy/util/compat.py", line 178, in raise_
    raise exception
  File "/home/henry/.virtualenvs/pydocs/lib/python3.8/site-packages/sqlalchemy/engine/base.py", line 1247, in _execute_context
    self.dialect.do_execute(
  File "/home/henry/.virtualenvs/pydocs/lib/python3.8/site-packages/sqlalchemy/engine/default.py", line 590, in do_execute
    cursor.execute(statement, parameters)
SystemError: <class 'pyodbc.Error'> returned a result with an error set

During handling of the above exception, another exception occurred:

Traceback (most recent call last):
  File "/home/henry/.virtualenvs/pydocs/lib/python3.8/site-packages/sqlalchemy/engine/base.py", line 733, in _rollback_impl
    self.engine.dialect.do_rollback(self.connection)
  File "/home/henry/.virtualenvs/pydocs/lib/python3.8/site-packages/sqlalchemy/engine/default.py", line 540, in do_rollback
    dbapi_connection.rollback()
pyodbc.OperationalError: ('08S01', '[08S01] [Microsoft][ODBC Driver 17 for SQL Server]Communication link failure (0) (SQLEndTran)')

The above exception was the direct cause of the following exception:

Traceback (most recent call last):
  File "/usr/lib/python3.8/runpy.py", line 193, in _run_module_as_main
    return _run_code(code, main_globals, None,
  File "/usr/lib/python3.8/runpy.py", line 86, in _run_code
    exec(code, run_globals)
  File "/home/henry/pydocs/processing/sql.py", line 277, in <module>
    start("testing" + datetime.now().__str__(), wpath)
  File "/home/henry/pydocs/processing/sql.py", line 238, in start
    sess.flush()
  File "/home/henry/.virtualenvs/pydocs/lib/python3.8/site-packages/sqlalchemy/orm/session.py", line 2496, in flush
    self._flush(objects)
  File "/home/henry/.virtualenvs/pydocs/lib/python3.8/site-packages/sqlalchemy/orm/session.py", line 2637, in _flush
    transaction.rollback(_capture_exception=True)
  File "/home/henry/.virtualenvs/pydocs/lib/python3.8/site-packages/sqlalchemy/util/langhelpers.py", line 81, in __exit__
    compat.raise_(value, with_traceback=traceback)
  File "/home/henry/.virtualenvs/pydocs/lib/python3.8/site-packages/sqlalchemy/util/compat.py", line 178, in raise_
    raise exception
  File "/home/henry/.virtualenvs/pydocs/lib/python3.8/site-packages/sqlalchemy/orm/session.py", line 2637, in _flush
    transaction.rollback(_capture_exception=True)
  File "/home/henry/.virtualenvs/pydocs/lib/python3.8/site-packages/sqlalchemy/orm/session.py", line 573, in rollback
    util.raise_(rollback_err[1], with_traceback=rollback_err[2])
  File "/home/henry/.virtualenvs/pydocs/lib/python3.8/site-packages/sqlalchemy/util/compat.py", line 178, in raise_
    raise exception
  File "/home/henry/.virtualenvs/pydocs/lib/python3.8/site-packages/sqlalchemy/orm/session.py", line 533, in rollback
    t[1].rollback()
  File "/home/henry/.virtualenvs/pydocs/lib/python3.8/site-packages/sqlalchemy/engine/base.py", line 1725, in rollback
    self._do_rollback()
  File "/home/henry/.virtualenvs/pydocs/lib/python3.8/site-packages/sqlalchemy/engine/base.py", line 1763, in _do_rollback
    self.connection._rollback_impl()
  File "/home/henry/.virtualenvs/pydocs/lib/python3.8/site-packages/sqlalchemy/engine/base.py", line 735, in _rollback_impl
    self._handle_dbapi_exception(e, None, None, None, None)
  File "/home/henry/.virtualenvs/pydocs/lib/python3.8/site-packages/sqlalchemy/engine/base.py", line 1481, in _handle_dbapi_exception
    util.raise_(
  File "/home/henry/.virtualenvs/pydocs/lib/python3.8/site-packages/sqlalchemy/util/compat.py", line 178, in raise_
    raise exception
  File "/home/henry/.virtualenvs/pydocs/lib/python3.8/site-packages/sqlalchemy/engine/base.py", line 733, in _rollback_impl
    self.engine.dialect.do_rollback(self.connection)
  File "/home/henry/.virtualenvs/pydocs/lib/python3.8/site-packages/sqlalchemy/engine/default.py", line 540, in do_rollback
    dbapi_connection.rollback()
sqlalchemy.exc.OperationalError: (pyodbc.OperationalError) ('08S01', '[08S01] [Microsoft][ODBC Driver 17 for SQL Server]Communication link failure (0) (SQLEndTran)')
(Background on this error at: http://sqlalche.me/e/e3q8)
configlo:26,08:58:47:mp_sendmail:115:7v22jQ -- sending mail
