sql.py:25,22:01:12:start:168:p-ARcw -- STARTING SQL testing2020-04-25 22:01:12.302767 /home/henry/pydocs/data/527e4afc-4598-400f-8536-afa5324f0ba4/
sql.py:25,22:01:12:start:170:p-ARcw -- setting sys except hook
sql.py:25,22:01:12:start:180:p-ARcw -- Owner name: testing2020-04-04 25 Apr6qaBGRrBtw
sql.py:25,22:01:13:start:184:p-ARcw -- Added owner row, name: testing2020-04-04 25 Apr6qaBGRrBtw id: 78
sql.py:25,22:01:13:load_from_dict:107:p-ARcw -- File: 0B4Fujvv5Mfqbb2d0TnNhcFhhREdadmRaaEI3QzVabnE2NE5v
configlo:25,22:01:13:handle_exception:82:p-ARcw -- Custom Uncaught exception
Traceback (most recent call last):
  File "/usr/lib/python3.8/runpy.py", line 193, in _run_module_as_main
    return _run_code(code, main_globals, None,
  File "/usr/lib/python3.8/runpy.py", line 86, in _run_code
    exec(code, run_globals)
  File "/home/henry/pydocs/processing/sql.py", line 264, in <module>
    start("testing" + datetime.now().__str__(), wpath)
  File "/home/henry/pydocs/processing/sql.py", line 190, in start
    load_from_dict(pickle.load(open(n, 'rb')), scoped_session())
  File "/home/henry/pydocs/processing/sql.py", line 120, in load_from_dict
    file_obj = Files(fileId = fileId + ":"+token,
NameError: name 'token' is not defined
configlo:25,22:01:13:mp_sendmail:115:p-ARcw -- sending mail
configlo:25,22:01:14:handle_exception:86:p-ARcw -- exiting! from sshook
