sql.py:25,13:00:25:<module>:24:we19Dw -- Driver%3D%7BODBC+Driver+17+for+SQL+Server%7D%3BServer%3Dtcp%3Apydoc-db.database.windows.net%2C1433%3BDatabase%3Dpydoc-db%3BUid%3Dhenry2833%3BPwd%3D%7BInfoip32%7D%3BEncrypt%3Dyes%3BTrustServerCertificate%3Dno%3BConnection+Timeout%3D30%3B
configlo:25,13:01:45:handle_exception:81:we19Dw -- Custom Uncaught exception
Traceback (most recent call last):
  File "/usr/lib/python3.8/encodings/utf_16_le.py", line 15, in decode
    def decode(input, errors='strict'):
KeyboardInterrupt

The above exception was the direct cause of the following exception:

KeyboardInterrupt: decoding with 'utf-16le' codec failed (KeyboardInterrupt: )

The above exception was the direct cause of the following exception:

Traceback (most recent call last):
  File "/home/henry/.virtualenvs/pydocs/lib/python3.8/site-packages/sqlalchemy/engine/base.py", line 1247, in _execute_context
    self.dialect.do_execute(
  File "/home/henry/.virtualenvs/pydocs/lib/python3.8/site-packages/sqlalchemy/engine/default.py", line 590, in do_execute
    cursor.execute(statement, parameters)
SystemError: <class 'pyodbc.Error'> returned a result with an error set

During handling of the above exception, another exception occurred:

Traceback (most recent call last):
  File "/home/henry/.virtualenvs/pydocs/lib/python3.8/site-packages/sqlalchemy/engine/base.py", line 733, in _rollback_impl
    self.engine.dialect.do_rollback(self.connection)
  File "/home/henry/.virtualenvs/pydocs/lib/python3.8/site-packages/sqlalchemy/engine/default.py", line 540, in do_rollback
    dbapi_connection.rollback()
pyodbc.OperationalError: ('08S01', '[08S01] [Microsoft][ODBC Driver 17 for SQL Server]Communication link failure (0) (SQLEndTran)')

The above exception was the direct cause of the following exception:

Traceback (most recent call last):
  File "dsds.py", line 1, in <module>
    from processing.get_files import loadFiles
  File "/home/henry/pydocs/processing/get_files.py", line 2, in <module>
    import processing.sql
  File "/home/henry/pydocs/processing/sql.py", line 30, in <module>
    Base.metadata.create_all(bind=ENGINE)
  File "/home/henry/.virtualenvs/pydocs/lib/python3.8/site-packages/sqlalchemy/sql/schema.py", line 4320, in create_all
    bind._run_visitor(
  File "/home/henry/.virtualenvs/pydocs/lib/python3.8/site-packages/sqlalchemy/engine/base.py", line 2058, in _run_visitor
    conn._run_visitor(visitorcallable, element, **kwargs)
  File "/home/henry/.virtualenvs/pydocs/lib/python3.8/site-packages/sqlalchemy/engine/base.py", line 1627, in _run_visitor
    visitorcallable(self.dialect, self, **kwargs).traverse_single(element)
  File "/home/henry/.virtualenvs/pydocs/lib/python3.8/site-packages/sqlalchemy/sql/visitors.py", line 144, in traverse_single
    return meth(obj, **kw)
  File "/home/henry/.virtualenvs/pydocs/lib/python3.8/site-packages/sqlalchemy/sql/ddl.py", line 754, in visit_metadata
    [t for t in tables if self._can_create_table(t)]
  File "/home/henry/.virtualenvs/pydocs/lib/python3.8/site-packages/sqlalchemy/sql/ddl.py", line 754, in <listcomp>
    [t for t in tables if self._can_create_table(t)]
  File "/home/henry/.virtualenvs/pydocs/lib/python3.8/site-packages/sqlalchemy/sql/ddl.py", line 730, in _can_create_table
    return not self.checkfirst or not self.dialect.has_table(
  File "/home/henry/.virtualenvs/pydocs/lib/python3.8/site-packages/sqlalchemy/dialects/mssql/base.py", line 2175, in wrap
    return _switch_db(
  File "/home/henry/.virtualenvs/pydocs/lib/python3.8/site-packages/sqlalchemy/dialects/mssql/base.py", line 2200, in _switch_db
    return fn(*arg, **kw)
  File "/home/henry/.virtualenvs/pydocs/lib/python3.8/site-packages/sqlalchemy/dialects/mssql/base.py", line 2448, in has_table
    c = connection.execute(s)
  File "/home/henry/.virtualenvs/pydocs/lib/python3.8/site-packages/sqlalchemy/engine/base.py", line 984, in execute
    return meth(self, multiparams, params)
  File "/home/henry/.virtualenvs/pydocs/lib/python3.8/site-packages/sqlalchemy/sql/elements.py", line 293, in _execute_on_connection
    return connection._execute_clauseelement(self, multiparams, params)
  File "/home/henry/.virtualenvs/pydocs/lib/python3.8/site-packages/sqlalchemy/engine/base.py", line 1097, in _execute_clauseelement
    ret = self._execute_context(
  File "/home/henry/.virtualenvs/pydocs/lib/python3.8/site-packages/sqlalchemy/engine/base.py", line 1287, in _execute_context
    self._handle_dbapi_exception(
  File "/home/henry/.virtualenvs/pydocs/lib/python3.8/site-packages/sqlalchemy/engine/base.py", line 1476, in _handle_dbapi_exception
    self._autorollback()
  File "/home/henry/.virtualenvs/pydocs/lib/python3.8/site-packages/sqlalchemy/util/langhelpers.py", line 81, in __exit__
    compat.raise_(value, with_traceback=traceback)
  File "/home/henry/.virtualenvs/pydocs/lib/python3.8/site-packages/sqlalchemy/util/compat.py", line 178, in raise_
    raise exception
  File "/home/henry/.virtualenvs/pydocs/lib/python3.8/site-packages/sqlalchemy/engine/base.py", line 1476, in _handle_dbapi_exception
    self._autorollback()
  File "/home/henry/.virtualenvs/pydocs/lib/python3.8/site-packages/sqlalchemy/engine/base.py", line 861, in _autorollback
    self._root._rollback_impl()
  File "/home/henry/.virtualenvs/pydocs/lib/python3.8/site-packages/sqlalchemy/engine/base.py", line 735, in _rollback_impl
    self._handle_dbapi_exception(e, None, None, None, None)
  File "/home/henry/.virtualenvs/pydocs/lib/python3.8/site-packages/sqlalchemy/engine/base.py", line 1376, in _handle_dbapi_exception
    util.raise_(
  File "/home/henry/.virtualenvs/pydocs/lib/python3.8/site-packages/sqlalchemy/util/compat.py", line 178, in raise_
    raise exception
  File "/home/henry/.virtualenvs/pydocs/lib/python3.8/site-packages/sqlalchemy/engine/base.py", line 733, in _rollback_impl
    self.engine.dialect.do_rollback(self.connection)
  File "/home/henry/.virtualenvs/pydocs/lib/python3.8/site-packages/sqlalchemy/engine/default.py", line 540, in do_rollback
    dbapi_connection.rollback()
sqlalchemy.exc.OperationalError: (pyodbc.OperationalError) ('08S01', '[08S01] [Microsoft][ODBC Driver 17 for SQL Server]Communication link failure (0) (SQLEndTran)')
(Background on this error at: http://sqlalche.me/e/e3q8)
