sql.py:25,12:58:53:<module>:24:CCR3vQ -- Driver%3D%7BODBC+Driver+17+for+SQL+Server%7D%3BServer%3Dtcp%3Apydoc-db.database.windows.net%2C1433%3BDatabase%3Dpydoc-db%3BUid%3Dhenry2833%3BPwd%3D%7BInfoip32%7D%3BEncrypt%3Dyes%3BTrustServerCertificate%3Dno%3BConnection+Timeout%3D30%3B
configlo:25,12:58:54:handle_exception:81:CCR3vQ -- Custom Uncaught exception
Traceback (most recent call last):
  File "/home/henry/.virtualenvs/pydocs/lib/python3.8/site-packages/sqlalchemy/engine/base.py", line 2285, in _wrap_pool_connect
    return fn()
  File "/home/henry/.virtualenvs/pydocs/lib/python3.8/site-packages/sqlalchemy/pool/base.py", line 363, in connect
    return _ConnectionFairy._checkout(self)
  File "/home/henry/.virtualenvs/pydocs/lib/python3.8/site-packages/sqlalchemy/pool/base.py", line 773, in _checkout
    fairy = _ConnectionRecord.checkout(pool)
  File "/home/henry/.virtualenvs/pydocs/lib/python3.8/site-packages/sqlalchemy/pool/base.py", line 492, in checkout
    rec = pool._do_get()
  File "/home/henry/.virtualenvs/pydocs/lib/python3.8/site-packages/sqlalchemy/pool/impl.py", line 139, in _do_get
    self._dec_overflow()
  File "/home/henry/.virtualenvs/pydocs/lib/python3.8/site-packages/sqlalchemy/util/langhelpers.py", line 68, in __exit__
    compat.raise_(
  File "/home/henry/.virtualenvs/pydocs/lib/python3.8/site-packages/sqlalchemy/util/compat.py", line 178, in raise_
    raise exception
  File "/home/henry/.virtualenvs/pydocs/lib/python3.8/site-packages/sqlalchemy/pool/impl.py", line 136, in _do_get
    return self._create_connection()
  File "/home/henry/.virtualenvs/pydocs/lib/python3.8/site-packages/sqlalchemy/pool/base.py", line 308, in _create_connection
    return _ConnectionRecord(self)
  File "/home/henry/.virtualenvs/pydocs/lib/python3.8/site-packages/sqlalchemy/pool/base.py", line 437, in __init__
    self.__connect(first_connect_check=True)
  File "/home/henry/.virtualenvs/pydocs/lib/python3.8/site-packages/sqlalchemy/pool/base.py", line 657, in __connect
    pool.logger.debug("Error on connect(): %s", e)
  File "/home/henry/.virtualenvs/pydocs/lib/python3.8/site-packages/sqlalchemy/util/langhelpers.py", line 68, in __exit__
    compat.raise_(
  File "/home/henry/.virtualenvs/pydocs/lib/python3.8/site-packages/sqlalchemy/util/compat.py", line 178, in raise_
    raise exception
  File "/home/henry/.virtualenvs/pydocs/lib/python3.8/site-packages/sqlalchemy/pool/base.py", line 652, in __connect
    connection = pool._invoke_creator(self)
  File "/home/henry/.virtualenvs/pydocs/lib/python3.8/site-packages/sqlalchemy/engine/strategies.py", line 114, in connect
    return dialect.connect(*cargs, **cparams)
  File "/home/henry/.virtualenvs/pydocs/lib/python3.8/site-packages/sqlalchemy/engine/default.py", line 490, in connect
    return self.dbapi.connect(*cargs, **cparams)
pyodbc.ProgrammingError: ('42000', "[42000] [Microsoft][ODBC Driver 17 for SQL Server][SQL Server]Database 'pydoc-db' on server 'pydoc-db' is not currently available.  Please retry the connection later.  If the problem persists, contact customer support, and provide them the session tracing ID of '9C73DB41-6B9B-4DC6-B2F3-E036839EE689'. (40613) (SQLDriverConnect)")

The above exception was the direct cause of the following exception:

Traceback (most recent call last):
  File "dsds.py", line 1, in <module>
    from processing.get_files import loadFiles
  File "/home/henry/pydocs/processing/get_files.py", line 2, in <module>
    import processing.sql
  File "/home/henry/pydocs/processing/sql.py", line 30, in <module>
    Base.metadata.create_all(bind=ENGINE)
  File "/home/henry/.virtualenvs/pydocs/lib/python3.8/site-packages/sqlalchemy/sql/schema.py", line 4320, in create_all
    bind._run_visitor(
  File "/home/henry/.virtualenvs/pydocs/lib/python3.8/site-packages/sqlalchemy/engine/base.py", line 2057, in _run_visitor
    with self._optional_conn_ctx_manager(connection) as conn:
  File "/usr/lib/python3.8/contextlib.py", line 113, in __enter__
    return next(self.gen)
  File "/home/henry/.virtualenvs/pydocs/lib/python3.8/site-packages/sqlalchemy/engine/base.py", line 2049, in _optional_conn_ctx_manager
    with self._contextual_connect() as conn:
  File "/home/henry/.virtualenvs/pydocs/lib/python3.8/site-packages/sqlalchemy/engine/base.py", line 2251, in _contextual_connect
    self._wrap_pool_connect(self.pool.connect, None),
  File "/home/henry/.virtualenvs/pydocs/lib/python3.8/site-packages/sqlalchemy/engine/base.py", line 2288, in _wrap_pool_connect
    Connection._handle_dbapi_exception_noconnection(
  File "/home/henry/.virtualenvs/pydocs/lib/python3.8/site-packages/sqlalchemy/engine/base.py", line 1554, in _handle_dbapi_exception_noconnection
    util.raise_(
  File "/home/henry/.virtualenvs/pydocs/lib/python3.8/site-packages/sqlalchemy/util/compat.py", line 178, in raise_
    raise exception
  File "/home/henry/.virtualenvs/pydocs/lib/python3.8/site-packages/sqlalchemy/engine/base.py", line 2285, in _wrap_pool_connect
    return fn()
  File "/home/henry/.virtualenvs/pydocs/lib/python3.8/site-packages/sqlalchemy/pool/base.py", line 363, in connect
    return _ConnectionFairy._checkout(self)
  File "/home/henry/.virtualenvs/pydocs/lib/python3.8/site-packages/sqlalchemy/pool/base.py", line 773, in _checkout
    fairy = _ConnectionRecord.checkout(pool)
  File "/home/henry/.virtualenvs/pydocs/lib/python3.8/site-packages/sqlalchemy/pool/base.py", line 492, in checkout
    rec = pool._do_get()
  File "/home/henry/.virtualenvs/pydocs/lib/python3.8/site-packages/sqlalchemy/pool/impl.py", line 139, in _do_get
    self._dec_overflow()
  File "/home/henry/.virtualenvs/pydocs/lib/python3.8/site-packages/sqlalchemy/util/langhelpers.py", line 68, in __exit__
    compat.raise_(
  File "/home/henry/.virtualenvs/pydocs/lib/python3.8/site-packages/sqlalchemy/util/compat.py", line 178, in raise_
    raise exception
  File "/home/henry/.virtualenvs/pydocs/lib/python3.8/site-packages/sqlalchemy/pool/impl.py", line 136, in _do_get
    return self._create_connection()
  File "/home/henry/.virtualenvs/pydocs/lib/python3.8/site-packages/sqlalchemy/pool/base.py", line 308, in _create_connection
    return _ConnectionRecord(self)
  File "/home/henry/.virtualenvs/pydocs/lib/python3.8/site-packages/sqlalchemy/pool/base.py", line 437, in __init__
    self.__connect(first_connect_check=True)
  File "/home/henry/.virtualenvs/pydocs/lib/python3.8/site-packages/sqlalchemy/pool/base.py", line 657, in __connect
    pool.logger.debug("Error on connect(): %s", e)
  File "/home/henry/.virtualenvs/pydocs/lib/python3.8/site-packages/sqlalchemy/util/langhelpers.py", line 68, in __exit__
    compat.raise_(
  File "/home/henry/.virtualenvs/pydocs/lib/python3.8/site-packages/sqlalchemy/util/compat.py", line 178, in raise_
    raise exception
  File "/home/henry/.virtualenvs/pydocs/lib/python3.8/site-packages/sqlalchemy/pool/base.py", line 652, in __connect
    connection = pool._invoke_creator(self)
  File "/home/henry/.virtualenvs/pydocs/lib/python3.8/site-packages/sqlalchemy/engine/strategies.py", line 114, in connect
    return dialect.connect(*cargs, **cparams)
  File "/home/henry/.virtualenvs/pydocs/lib/python3.8/site-packages/sqlalchemy/engine/default.py", line 490, in connect
    return self.dbapi.connect(*cargs, **cparams)
sqlalchemy.exc.ProgrammingError: (pyodbc.ProgrammingError) ('42000', "[42000] [Microsoft][ODBC Driver 17 for SQL Server][SQL Server]Database 'pydoc-db' on server 'pydoc-db' is not currently available.  Please retry the connection later.  If the problem persists, contact customer support, and provide them the session tracing ID of '9C73DB41-6B9B-4DC6-B2F3-E036839EE689'. (40613) (SQLDriverConnect)")
(Background on this error at: http://sqlalche.me/e/f405)
configlo:25,12:58:56:handle_exception:85:CCR3vQ -- exiting! from sshook
