sql.py:25,22:08:10:start:170:p258GA -- STARTING SQL testing2020-04-25 22:08:10.351201 /home/henry/pydocs/data/527e4afc-4598-400f-8536-afa5324f0ba4/
sql.py:25,22:08:10:start:172:p258GA -- setting sys except hook
sql.py:25,22:08:10:start:180:p258GA -- Owner name: testing2020-04-04 25 AprO7WG31Oqtg
sql.py:25,22:08:11:start:184:p258GA -- Added owner row, name: testing2020-04-04 25 AprO7WG31Oqtg id: 83
configlo:25,22:08:11:handle_exception:82:p258GA -- Custom Uncaught exception
Traceback (most recent call last):
  File "/usr/lib/python3.8/runpy.py", line 193, in _run_module_as_main
    return _run_code(code, main_globals, None,
  File "/usr/lib/python3.8/runpy.py", line 86, in _run_code
    exec(code, run_globals)
  File "/home/henry/pydocs/processing/sql.py", line 268, in <module>
    start("testing" + datetime.now().__str__(), wpath)
  File "/home/henry/pydocs/processing/sql.py", line 194, in start
    i.join()
  File "/usr/lib/python3.8/multiprocessing/process.py", line 148, in join
    assert self._popen is not None, 'can only join a started process'
AssertionError: can only join a started process
configlo:25,22:08:11:mp_sendmail:115:p258GA -- sending mail
configlo:25,22:08:12:handle_exception:86:p258GA -- exiting! from sshook
