configlo:01,17:45:43:handle_exception:84:88qpBQ -- Custom Uncaught exception
Traceback (most recent call last):
  File "/home/henry/pydocs/run.py", line 28, in <module>
    app = create_flask_serv()
  File "/home/henry/pydocs/flaskr/__init__.py", line 14, in create_flask_serv
    from flaskr.dashapp import register_dashapp
  File "/home/henry/pydocs/flaskr/dashapp/__init__.py", line 2, in <module>
    from flaskr.dashapp.callbacks import test
  File "/home/henry/pydocs/flaskr/dashapp/callbacks.py", line 7, in <module>
    from processing.sql import v_scoped_session
  File "/home/henry/pydocs/processing/sql.py", line 34, in <module>
    Base.metadata.create_all(bind=ENGINE)
  File "/home/henry/.virtualenvs/pydocs/lib/python3.8/site-packages/sqlalchemy/sql/schema.py", line 4320, in create_all
    bind._run_visitor(
  File "/home/henry/.virtualenvs/pydocs/lib/python3.8/site-packages/sqlalchemy/engine/base.py", line 2057, in _run_visitor
    with self._optional_conn_ctx_manager(connection) as conn:
  File "/usr/lib/python3.8/contextlib.py", line 113, in __enter__
    return next(self.gen)
  File "/home/henry/.virtualenvs/pydocs/lib/python3.8/site-packages/sqlalchemy/engine/base.py", line 2049, in _optional_conn_ctx_manager
    with self._contextual_connect() as conn:
  File "/home/henry/.virtualenvs/pydocs/lib/python3.8/site-packages/sqlalchemy/engine/base.py", line 2251, in _contextual_connect
    self._wrap_pool_connect(self.pool.connect, None),
  File "/home/henry/.virtualenvs/pydocs/lib/python3.8/site-packages/sqlalchemy/engine/base.py", line 2285, in _wrap_pool_connect
    return fn()
  File "/home/henry/.virtualenvs/pydocs/lib/python3.8/site-packages/sqlalchemy/pool/base.py", line 363, in connect
    return _ConnectionFairy._checkout(self)
  File "/home/henry/.virtualenvs/pydocs/lib/python3.8/site-packages/sqlalchemy/pool/base.py", line 773, in _checkout
    fairy = _ConnectionRecord.checkout(pool)
  File "/home/henry/.virtualenvs/pydocs/lib/python3.8/site-packages/sqlalchemy/pool/base.py", line 492, in checkout
    rec = pool._do_get()
  File "/home/henry/.virtualenvs/pydocs/lib/python3.8/site-packages/sqlalchemy/pool/impl.py", line 139, in _do_get
    self._dec_overflow()
  File "/home/henry/.virtualenvs/pydocs/lib/python3.8/site-packages/sqlalchemy/util/langhelpers.py", line 68, in __exit__
    compat.raise_(
  File "/home/henry/.virtualenvs/pydocs/lib/python3.8/site-packages/sqlalchemy/util/compat.py", line 178, in raise_
    raise exception
  File "/home/henry/.virtualenvs/pydocs/lib/python3.8/site-packages/sqlalchemy/pool/impl.py", line 136, in _do_get
    return self._create_connection()
  File "/home/henry/.virtualenvs/pydocs/lib/python3.8/site-packages/sqlalchemy/pool/base.py", line 308, in _create_connection
    return _ConnectionRecord(self)
  File "/home/henry/.virtualenvs/pydocs/lib/python3.8/site-packages/sqlalchemy/pool/base.py", line 437, in __init__
    self.__connect(first_connect_check=True)
  File "/home/henry/.virtualenvs/pydocs/lib/python3.8/site-packages/sqlalchemy/pool/base.py", line 652, in __connect
    connection = pool._invoke_creator(self)
  File "/home/henry/.virtualenvs/pydocs/lib/python3.8/site-packages/sqlalchemy/engine/strategies.py", line 114, in connect
    return dialect.connect(*cargs, **cparams)
  File "/home/henry/.virtualenvs/pydocs/lib/python3.8/site-packages/sqlalchemy/engine/default.py", line 490, in connect
    return self.dbapi.connect(*cargs, **cparams)
KeyboardInterrupt
configlo:01,17:45:43:mp_sendmail:121:88qpBQ -- sending mail
