configlo:27,11:54:11:handle_exception:84:How2bw -- Custom Uncaught exception
Traceback (most recent call last):
  File "/usr/lib/python3.8/encodings/utf_16_le.py", line 15, in decode
    def decode(input, errors='strict'):
KeyboardInterrupt

The above exception was the direct cause of the following exception:

KeyboardInterrupt: decoding with 'utf-16le' codec failed (KeyboardInterrupt: )

The above exception was the direct cause of the following exception:

Traceback (most recent call last):
  File "/home/henry/.virtualenvs/pydocs/lib/python3.8/site-packages/sqlalchemy/engine/base.py", line 1322, in _cursor_execute
    self.dialect.do_execute(cursor, statement, parameters, context)
  File "/home/henry/.virtualenvs/pydocs/lib/python3.8/site-packages/sqlalchemy/engine/default.py", line 590, in do_execute
    cursor.execute(statement, parameters)
SystemError: <class 'pyodbc.Error'> returned a result with an error set

The above exception was the direct cause of the following exception:

Traceback (most recent call last):
  File "/usr/lib/python3.8/runpy.py", line 193, in _run_module_as_main
    return _run_code(code, main_globals, None,
  File "/usr/lib/python3.8/runpy.py", line 86, in _run_code
    exec(code, run_globals)
  File "/home/henry/pydocs/processing/sql.py", line 26, in <module>
    Base.metadata.create_all(bind=ENGINE)
  File "/home/henry/.virtualenvs/pydocs/lib/python3.8/site-packages/sqlalchemy/sql/schema.py", line 4320, in create_all
    bind._run_visitor(
  File "/home/henry/.virtualenvs/pydocs/lib/python3.8/site-packages/sqlalchemy/engine/base.py", line 2057, in _run_visitor
    with self._optional_conn_ctx_manager(connection) as conn:
  File "/usr/lib/python3.8/contextlib.py", line 113, in __enter__
    return next(self.gen)
  File "/home/henry/.virtualenvs/pydocs/lib/python3.8/site-packages/sqlalchemy/engine/base.py", line 2049, in _optional_conn_ctx_manager
    with self._contextual_connect() as conn:
  File "/home/henry/.virtualenvs/pydocs/lib/python3.8/site-packages/sqlalchemy/engine/base.py", line 2251, in _contextual_connect
    self._wrap_pool_connect(self.pool.connect, None),
  File "/home/henry/.virtualenvs/pydocs/lib/python3.8/site-packages/sqlalchemy/engine/base.py", line 2285, in _wrap_pool_connect
    return fn()
  File "/home/henry/.virtualenvs/pydocs/lib/python3.8/site-packages/sqlalchemy/pool/base.py", line 363, in connect
    return _ConnectionFairy._checkout(self)
  File "/home/henry/.virtualenvs/pydocs/lib/python3.8/site-packages/sqlalchemy/pool/base.py", line 773, in _checkout
    fairy = _ConnectionRecord.checkout(pool)
  File "/home/henry/.virtualenvs/pydocs/lib/python3.8/site-packages/sqlalchemy/pool/base.py", line 492, in checkout
    rec = pool._do_get()
  File "/home/henry/.virtualenvs/pydocs/lib/python3.8/site-packages/sqlalchemy/pool/impl.py", line 139, in _do_get
    self._dec_overflow()
  File "/home/henry/.virtualenvs/pydocs/lib/python3.8/site-packages/sqlalchemy/util/langhelpers.py", line 68, in __exit__
    compat.raise_(
  File "/home/henry/.virtualenvs/pydocs/lib/python3.8/site-packages/sqlalchemy/util/compat.py", line 178, in raise_
    raise exception
  File "/home/henry/.virtualenvs/pydocs/lib/python3.8/site-packages/sqlalchemy/pool/impl.py", line 136, in _do_get
    return self._create_connection()
  File "/home/henry/.virtualenvs/pydocs/lib/python3.8/site-packages/sqlalchemy/pool/base.py", line 308, in _create_connection
    return _ConnectionRecord(self)
  File "/home/henry/.virtualenvs/pydocs/lib/python3.8/site-packages/sqlalchemy/pool/base.py", line 437, in __init__
    self.__connect(first_connect_check=True)
  File "/home/henry/.virtualenvs/pydocs/lib/python3.8/site-packages/sqlalchemy/pool/base.py", line 660, in __connect
    pool.dispatch.first_connect.for_modify(
  File "/home/henry/.virtualenvs/pydocs/lib/python3.8/site-packages/sqlalchemy/event/attr.py", line 314, in exec_once_unless_exception
    self._exec_once_impl(True, *args, **kw)
  File "/home/henry/.virtualenvs/pydocs/lib/python3.8/site-packages/sqlalchemy/event/attr.py", line 285, in _exec_once_impl
    self(*args, **kw)
  File "/home/henry/.virtualenvs/pydocs/lib/python3.8/site-packages/sqlalchemy/event/attr.py", line 322, in __call__
    fn(*args, **kw)
  File "/home/henry/.virtualenvs/pydocs/lib/python3.8/site-packages/sqlalchemy/util/langhelpers.py", line 1513, in go
    return once_fn(*arg, **kw)
  File "/home/henry/.virtualenvs/pydocs/lib/python3.8/site-packages/sqlalchemy/engine/strategies.py", line 199, in first_connect
    dialect.initialize(c)
  File "/home/henry/.virtualenvs/pydocs/lib/python3.8/site-packages/sqlalchemy/dialects/mssql/base.py", line 2392, in initialize
    super(MSDialect, self).initialize(connection)
  File "/home/henry/.virtualenvs/pydocs/lib/python3.8/site-packages/sqlalchemy/engine/default.py", line 328, in initialize
    self.returns_unicode_strings = self._check_unicode_returns(connection)
  File "/home/henry/.virtualenvs/pydocs/lib/python3.8/site-packages/sqlalchemy/engine/default.py", line 415, in _check_unicode_returns
    results = {check_unicode(test) for test in tests}
  File "/home/henry/.virtualenvs/pydocs/lib/python3.8/site-packages/sqlalchemy/engine/default.py", line 415, in <setcomp>
    results = {check_unicode(test) for test in tests}
  File "/home/henry/.virtualenvs/pydocs/lib/python3.8/site-packages/sqlalchemy/engine/default.py", line 384, in check_unicode
    connection._cursor_execute(cursor, statement, parameters)
  File "/home/henry/.virtualenvs/pydocs/lib/python3.8/site-packages/sqlalchemy/engine/base.py", line 1324, in _cursor_execute
    self._handle_dbapi_exception(
  File "/home/henry/.virtualenvs/pydocs/lib/python3.8/site-packages/sqlalchemy/engine/base.py", line 1481, in _handle_dbapi_exception
    util.raise_(
  File "/home/henry/.virtualenvs/pydocs/lib/python3.8/site-packages/sqlalchemy/util/compat.py", line 178, in raise_
    raise exception
  File "/home/henry/.virtualenvs/pydocs/lib/python3.8/site-packages/sqlalchemy/engine/base.py", line 1322, in _cursor_execute
    self.dialect.do_execute(cursor, statement, parameters, context)
  File "/home/henry/.virtualenvs/pydocs/lib/python3.8/site-packages/sqlalchemy/engine/default.py", line 590, in do_execute
    cursor.execute(statement, parameters)
sqlalchemy.exc.StatementError: (builtins.SystemError) <class 'pyodbc.Error'> returned a result with an error set
[SQL: SELECT CAST('test plain returns' AS VARCHAR(60)) AS anon_1]
configlo:27,11:54:11:handle_exception:88:How2bw -- exiting! from sshook
